[2024-10-14 16:29:22,849] - [phase.py file line:636] - INFO: **[do you have any unittestcode]**:

[False, False, False, False]
[2024-10-14 16:29:22,849] - [phase.py file line:636] - INFO: **[do you have any unittestcode]**:

[False, False, False, False]
[2024-10-14 16:29:22,849] - [phase.py file line:636] - INFO: **[do you have any unittestcode]**:

[False, False, False, False]
[2024-10-14 16:29:22,849] - [phase.py file line:636] - INFO: **[do you have any unittestcode]**:

[False, False, False, False]
[2024-10-14 16:29:22,849] - [phase.py file line:636] - INFO: **[do you have any unittestcode]**:

[False, False, False, False]
[2024-10-14 16:29:22,852] - [phase.py file line:661] - INFO: **[Unit Test Reports_desc]**:

**no unit test reports yet**
[2024-10-14 16:29:22,852] - [phase.py file line:661] - INFO: **[Unit Test Reports_desc]**:

**no unit test reports yet**
[2024-10-14 16:29:22,852] - [phase.py file line:661] - INFO: **[Unit Test Reports_desc]**:

**no unit test reports yet**
[2024-10-14 16:29:22,852] - [phase.py file line:661] - INFO: **[Unit Test Reports_desc]**:

**no unit test reports yet**
[2024-10-14 16:29:22,852] - [phase.py file line:661] - INFO: **[Unit Test Reports_desc]**:

**no unit test reports yet**
[2024-10-14 16:29:22,852] - [phase.py file line:636] - INFO: **[do you have any unittestcode]**:

[False, False, False, False]
[2024-10-14 16:29:22,852] - [phase.py file line:636] - INFO: **[do you have any unittestcode]**:

[False, False, False, False]
[2024-10-14 16:29:22,852] - [phase.py file line:636] - INFO: **[do you have any unittestcode]**:

[False, False, False, False]
[2024-10-14 16:29:22,852] - [phase.py file line:636] - INFO: **[do you have any unittestcode]**:

[False, False, False, False]
[2024-10-14 16:29:22,852] - [phase.py file line:636] - INFO: **[do you have any unittestcode]**:

[False, False, False, False]
[2024-10-14 16:29:22,853] - [phase.py file line:661] - INFO: **[Unit Test Reports_desc]**:

**no unit test reports yet**
[2024-10-14 16:29:22,853] - [phase.py file line:661] - INFO: **[Unit Test Reports_desc]**:

**no unit test reports yet**
[2024-10-14 16:29:22,853] - [phase.py file line:661] - INFO: **[Unit Test Reports_desc]**:

**no unit test reports yet**
[2024-10-14 16:29:22,853] - [phase.py file line:661] - INFO: **[Unit Test Reports_desc]**:

**no unit test reports yet**
[2024-10-14 16:29:22,853] - [phase.py file line:661] - INFO: **[Unit Test Reports_desc]**:

**no unit test reports yet**
[2024-10-14 16:29:32,070] - [phase.py file line:636] - INFO: **[do you have any unittestcode]**:

[False, False, False, False, True]
[2024-10-14 16:29:32,070] - [phase.py file line:636] - INFO: **[do you have any unittestcode]**:

[False, False, False, False, True]
[2024-10-14 16:29:32,070] - [phase.py file line:636] - INFO: **[do you have any unittestcode]**:

[False, False, False, False, True]
[2024-10-14 16:29:32,070] - [phase.py file line:636] - INFO: **[do you have any unittestcode]**:

[False, False, False, False, True]
[2024-10-14 16:29:32,070] - [phase.py file line:636] - INFO: **[do you have any unittestcode]**:

[False, False, False, False, True]
[2024-10-14 16:29:35,084] - [phase.py file line:649] - INFO: **[Unit Test Reports]**:

Traceback (most recent call last):
  File "C:\SI-Follow\ChatDev\WareHouse\111111111111\test999\unittest_main.py", line 7, in <module>
    test_suite = test_loader.loadTestsFromFile("unittest_calculator.py")
AttributeError: 'TestLoader' object has no attribute 'loadTestsFromFile'. Did you mean: 'loadTestsFromName'?

[2024-10-14 16:29:35,084] - [phase.py file line:649] - INFO: **[Unit Test Reports]**:

Traceback (most recent call last):
  File "C:\SI-Follow\ChatDev\WareHouse\111111111111\test999\unittest_main.py", line 7, in <module>
    test_suite = test_loader.loadTestsFromFile("unittest_calculator.py")
AttributeError: 'TestLoader' object has no attribute 'loadTestsFromFile'. Did you mean: 'loadTestsFromName'?

[2024-10-14 16:29:35,084] - [phase.py file line:649] - INFO: **[Unit Test Reports]**:

Traceback (most recent call last):
  File "C:\SI-Follow\ChatDev\WareHouse\111111111111\test999\unittest_main.py", line 7, in <module>
    test_suite = test_loader.loadTestsFromFile("unittest_calculator.py")
AttributeError: 'TestLoader' object has no attribute 'loadTestsFromFile'. Did you mean: 'loadTestsFromName'?

[2024-10-14 16:29:35,084] - [phase.py file line:649] - INFO: **[Unit Test Reports]**:

Traceback (most recent call last):
  File "C:\SI-Follow\ChatDev\WareHouse\111111111111\test999\unittest_main.py", line 7, in <module>
    test_suite = test_loader.loadTestsFromFile("unittest_calculator.py")
AttributeError: 'TestLoader' object has no attribute 'loadTestsFromFile'. Did you mean: 'loadTestsFromName'?

[2024-10-14 16:29:35,084] - [phase.py file line:649] - INFO: **[Unit Test Reports]**:

Traceback (most recent call last):
  File "C:\SI-Follow\ChatDev\WareHouse\111111111111\test999\unittest_main.py", line 7, in <module>
    test_suite = test_loader.loadTestsFromFile("unittest_calculator.py")
AttributeError: 'TestLoader' object has no attribute 'loadTestsFromFile'. Did you mean: 'loadTestsFromName'?

[2024-10-14 16:29:35,088] - [phase.py file line:636] - INFO: **[do you have any unittestcode]**:

[False, False, False, False, True]
[2024-10-14 16:29:35,088] - [phase.py file line:636] - INFO: **[do you have any unittestcode]**:

[False, False, False, False, True]
[2024-10-14 16:29:35,088] - [phase.py file line:636] - INFO: **[do you have any unittestcode]**:

[False, False, False, False, True]
[2024-10-14 16:29:35,088] - [phase.py file line:636] - INFO: **[do you have any unittestcode]**:

[False, False, False, False, True]
[2024-10-14 16:29:35,088] - [phase.py file line:636] - INFO: **[do you have any unittestcode]**:

[False, False, False, False, True]
[2024-10-14 16:29:38,110] - [phase.py file line:649] - INFO: **[Unit Test Reports]**:

Traceback (most recent call last):
  File "C:\SI-Follow\ChatDev\WareHouse\111111111111\test999\unittest_main.py", line 7, in <module>
    test_suite = test_loader.loadTestsFromFile("unittest_calculator.py")
AttributeError: 'TestLoader' object has no attribute 'loadTestsFromFile'. Did you mean: 'loadTestsFromName'?

[2024-10-14 16:29:38,110] - [phase.py file line:649] - INFO: **[Unit Test Reports]**:

Traceback (most recent call last):
  File "C:\SI-Follow\ChatDev\WareHouse\111111111111\test999\unittest_main.py", line 7, in <module>
    test_suite = test_loader.loadTestsFromFile("unittest_calculator.py")
AttributeError: 'TestLoader' object has no attribute 'loadTestsFromFile'. Did you mean: 'loadTestsFromName'?

[2024-10-14 16:29:38,110] - [phase.py file line:649] - INFO: **[Unit Test Reports]**:

Traceback (most recent call last):
  File "C:\SI-Follow\ChatDev\WareHouse\111111111111\test999\unittest_main.py", line 7, in <module>
    test_suite = test_loader.loadTestsFromFile("unittest_calculator.py")
AttributeError: 'TestLoader' object has no attribute 'loadTestsFromFile'. Did you mean: 'loadTestsFromName'?

[2024-10-14 16:29:38,110] - [phase.py file line:649] - INFO: **[Unit Test Reports]**:

Traceback (most recent call last):
  File "C:\SI-Follow\ChatDev\WareHouse\111111111111\test999\unittest_main.py", line 7, in <module>
    test_suite = test_loader.loadTestsFromFile("unittest_calculator.py")
AttributeError: 'TestLoader' object has no attribute 'loadTestsFromFile'. Did you mean: 'loadTestsFromName'?

[2024-10-14 16:29:38,110] - [phase.py file line:649] - INFO: **[Unit Test Reports]**:

Traceback (most recent call last):
  File "C:\SI-Follow\ChatDev\WareHouse\111111111111\test999\unittest_main.py", line 7, in <module>
    test_suite = test_loader.loadTestsFromFile("unittest_calculator.py")
AttributeError: 'TestLoader' object has no attribute 'loadTestsFromFile'. Did you mean: 'loadTestsFromName'?

[2024-10-14 16:29:49,349] - [phase.py file line:636] - INFO: **[do you have any unittestcode]**:

[False, False, False, False, True]
[2024-10-14 16:29:49,349] - [phase.py file line:636] - INFO: **[do you have any unittestcode]**:

[False, False, False, False, True]
[2024-10-14 16:29:49,349] - [phase.py file line:636] - INFO: **[do you have any unittestcode]**:

[False, False, False, False, True]
[2024-10-14 16:29:49,349] - [phase.py file line:636] - INFO: **[do you have any unittestcode]**:

[False, False, False, False, True]
[2024-10-14 16:29:49,349] - [phase.py file line:636] - INFO: **[do you have any unittestcode]**:

[False, False, False, False, True]
[2024-10-14 16:29:52,355] - [phase.py file line:649] - INFO: **[Unit Test Reports]**:

Traceback (most recent call last):
  File "C:\SI-Follow\ChatDev\WareHouse\111111111111\test999\unittest_main.py", line 5, in <module>
    from unittest_calculator import TestCalculator
ModuleNotFoundError: No module named 'unittest_calculator'

[2024-10-14 16:29:52,355] - [phase.py file line:649] - INFO: **[Unit Test Reports]**:

Traceback (most recent call last):
  File "C:\SI-Follow\ChatDev\WareHouse\111111111111\test999\unittest_main.py", line 5, in <module>
    from unittest_calculator import TestCalculator
ModuleNotFoundError: No module named 'unittest_calculator'

[2024-10-14 16:29:52,355] - [phase.py file line:649] - INFO: **[Unit Test Reports]**:

Traceback (most recent call last):
  File "C:\SI-Follow\ChatDev\WareHouse\111111111111\test999\unittest_main.py", line 5, in <module>
    from unittest_calculator import TestCalculator
ModuleNotFoundError: No module named 'unittest_calculator'

[2024-10-14 16:29:52,355] - [phase.py file line:649] - INFO: **[Unit Test Reports]**:

Traceback (most recent call last):
  File "C:\SI-Follow\ChatDev\WareHouse\111111111111\test999\unittest_main.py", line 5, in <module>
    from unittest_calculator import TestCalculator
ModuleNotFoundError: No module named 'unittest_calculator'

[2024-10-14 16:29:52,355] - [phase.py file line:649] - INFO: **[Unit Test Reports]**:

Traceback (most recent call last):
  File "C:\SI-Follow\ChatDev\WareHouse\111111111111\test999\unittest_main.py", line 5, in <module>
    from unittest_calculator import TestCalculator
ModuleNotFoundError: No module named 'unittest_calculator'

[2024-10-14 16:29:52,359] - [phase.py file line:636] - INFO: **[do you have any unittestcode]**:

[False, False, False, False, True]
[2024-10-14 16:29:52,359] - [phase.py file line:636] - INFO: **[do you have any unittestcode]**:

[False, False, False, False, True]
[2024-10-14 16:29:52,359] - [phase.py file line:636] - INFO: **[do you have any unittestcode]**:

[False, False, False, False, True]
[2024-10-14 16:29:52,359] - [phase.py file line:636] - INFO: **[do you have any unittestcode]**:

[False, False, False, False, True]
[2024-10-14 16:29:52,359] - [phase.py file line:636] - INFO: **[do you have any unittestcode]**:

[False, False, False, False, True]
[2024-10-14 16:29:55,374] - [phase.py file line:649] - INFO: **[Unit Test Reports]**:

Traceback (most recent call last):
  File "C:\SI-Follow\ChatDev\WareHouse\111111111111\test999\unittest_main.py", line 5, in <module>
    from unittest_calculator import TestCalculator
ModuleNotFoundError: No module named 'unittest_calculator'

[2024-10-14 16:29:55,374] - [phase.py file line:649] - INFO: **[Unit Test Reports]**:

Traceback (most recent call last):
  File "C:\SI-Follow\ChatDev\WareHouse\111111111111\test999\unittest_main.py", line 5, in <module>
    from unittest_calculator import TestCalculator
ModuleNotFoundError: No module named 'unittest_calculator'

[2024-10-14 16:29:55,374] - [phase.py file line:649] - INFO: **[Unit Test Reports]**:

Traceback (most recent call last):
  File "C:\SI-Follow\ChatDev\WareHouse\111111111111\test999\unittest_main.py", line 5, in <module>
    from unittest_calculator import TestCalculator
ModuleNotFoundError: No module named 'unittest_calculator'

[2024-10-14 16:29:55,374] - [phase.py file line:649] - INFO: **[Unit Test Reports]**:

Traceback (most recent call last):
  File "C:\SI-Follow\ChatDev\WareHouse\111111111111\test999\unittest_main.py", line 5, in <module>
    from unittest_calculator import TestCalculator
ModuleNotFoundError: No module named 'unittest_calculator'

[2024-10-14 16:29:55,374] - [phase.py file line:649] - INFO: **[Unit Test Reports]**:

Traceback (most recent call last):
  File "C:\SI-Follow\ChatDev\WareHouse\111111111111\test999\unittest_main.py", line 5, in <module>
    from unittest_calculator import TestCalculator
ModuleNotFoundError: No module named 'unittest_calculator'

[2024-10-14 16:29:55,377] - [phase.py file line:673] - INFO: ModuleNotFoundError found in Unit Test Reports:
Traceback (most recent call last):
  File "C:\SI-Follow\ChatDev\WareHouse\111111111111\test999\unittest_main.py", line 5, in <module>
    from unittest_calculator import TestCalculator
ModuleNotFoundError: No module named 'unittest_calculator'


[2024-10-14 16:29:55,377] - [phase.py file line:673] - INFO: ModuleNotFoundError found in Unit Test Reports:
Traceback (most recent call last):
  File "C:\SI-Follow\ChatDev\WareHouse\111111111111\test999\unittest_main.py", line 5, in <module>
    from unittest_calculator import TestCalculator
ModuleNotFoundError: No module named 'unittest_calculator'


[2024-10-14 16:29:55,377] - [phase.py file line:673] - INFO: ModuleNotFoundError found in Unit Test Reports:
Traceback (most recent call last):
  File "C:\SI-Follow\ChatDev\WareHouse\111111111111\test999\unittest_main.py", line 5, in <module>
    from unittest_calculator import TestCalculator
ModuleNotFoundError: No module named 'unittest_calculator'


[2024-10-14 16:29:55,377] - [phase.py file line:673] - INFO: ModuleNotFoundError found in Unit Test Reports:
Traceback (most recent call last):
  File "C:\SI-Follow\ChatDev\WareHouse\111111111111\test999\unittest_main.py", line 5, in <module>
    from unittest_calculator import TestCalculator
ModuleNotFoundError: No module named 'unittest_calculator'


[2024-10-14 16:29:55,377] - [phase.py file line:673] - INFO: ModuleNotFoundError found in Unit Test Reports:
Traceback (most recent call last):
  File "C:\SI-Follow\ChatDev\WareHouse\111111111111\test999\unittest_main.py", line 5, in <module>
    from unittest_calculator import TestCalculator
ModuleNotFoundError: No module named 'unittest_calculator'


[2024-10-14 16:29:56,636] - [phase.py file line:682] - ERROR: Failed to install the following modules: ['unittest_calculator']
[2024-10-14 16:29:56,636] - [phase.py file line:682] - ERROR: Failed to install the following modules: ['unittest_calculator']
[2024-10-14 16:29:56,636] - [phase.py file line:682] - ERROR: Failed to install the following modules: ['unittest_calculator']
[2024-10-14 16:29:56,636] - [phase.py file line:682] - ERROR: Failed to install the following modules: ['unittest_calculator']
[2024-10-14 16:29:56,636] - [phase.py file line:682] - ERROR: Failed to install the following modules: ['unittest_calculator']
